Workbook
Name __Anonymous_Sheet_DB__1: #REF!
Name __Anonymous_Sheet_DB__1: #REF!
Name __Anonymous_Sheet_DB__1: #REF!
Name __Anonymous_Sheet_DB__1: #REF!
Name __Anonymous_Sheet_DB__1: #REF!
Name __Anonymous_Sheet_DB__1: #REF!
Name __Anonymous_Sheet_DB__1: #REF!
Name __Anonymous_Sheet_DB__1: #REF!
Name __Anonymous_Sheet_DB__1: #REF!
Name __Anonymous_Sheet_DB__1: #REF!
Name __Anonymous_Sheet_DB__1: #REF!
Name __Anonymous_Sheet_DB__1: #REF!
Name __Anonymous_Sheet_DB__1: #REF!
Name __Anonymous_Sheet_DB__1: #REF!
Name __Anonymous_Sheet_DB__1: #REF!
Name __Anonymous_Sheet_DB__1: #REF!
Name __Anonymous_Sheet_DB__1: #REF!
Name __Anonymous_Sheet_DB__1: #REF!
Name __Anonymous_Sheet_DB__1: #REF!
Name __Anonymous_Sheet_DB__1: #REF!
Name __Anonymous_Sheet_DB__1: #REF!
Name __Anonymous_Sheet_DB__1_1: #REF!
Name __Anonymous_Sheet_DB__1_1: #REF!
Name __Anonymous_Sheet_DB__1_1: #REF!
Name __Anonymous_Sheet_DB__2: #REF!
Name __Anonymous_Sheet_DB__2: #REF!
Name __Anonymous_Sheet_DB__2: #REF!
Name _FilterDatabase_1: #REF!
Name _FilterDatabase_1: #REF!
Name _FilterDatabase_1_1: #REF!
Name _FilterDatabase_1_1: #REF!
Name _FilterDatabase_2: #REF!
Name _FilterDatabase_2: #REF!
Name sss: #REF!
Name sss: #REF!
Name sss: #REF!
Name sss: #REF!
Name sss: #REF!
Name sss: #REF!
Name sss: #REF!
Name sss: #REF!
Name sss: #REF!
Name sss: #REF!
Name sss: #REF!
Name sss: #REF!
Name sss: #REF!
Name sss: #REF!
Name sss: #REF!
Name sss: #REF!
Name sss: #REF!
Name sss: #REF!
Name sss: #REF!
Name sss: #REF!
Name sss: #REF!

Sheet 113年12月
A4: =總表!$A$6 -> 113年12月
A5: =總表!$E$6 -> 居服員 | B5: =總表!$D$6 -> N0174 | C5: =總表!$F$6 -> 曾馨幼
A6: 項目(A1) | B6: 薪資/小時 (a) | C6: 200
B7: 工作加給/小時 (aa)
B8: 平日服務時數 (b) | C8: =總表!$O$6 -> 167.17
B9: 本薪 (c) | C9: =總表!$T$6 -> 33434
B10: 平日加班加給/小時 (d) | C10: 66
B11: 平日加班時數 (e) | C11: =總表!$P$6 -> 0.17
B12: 平日延長加班/假日(休息及國定) 加給/小時 (f) | C12: 200
B13: 延長加班+例假日服務時數 (g) | C13: =總表!$R$6 -> 33.83
B14: 總加班費 (h) | C14: =總表!$U$6 -> 13577
B15: 津貼/小時 (i) | C15: 50
B16: 總津貼(50*總工作時數 ) (j) | C16: =總表!$V$6 -> 10059
A17: 獎金(A2) | C17: =總表!$W$6 -> 0
A18: 應發薪資(A) | B18: A1(c+h+j)+A2 | C18: =總表!$X$6 -> 57070
A19: 個人扣項 | B19: 勞保費(45800) (k) | C19: =總表!$AA$6 -> 1100
B20: 健保費(53000) (l) | C20: =總表!$AC$6 -> 1644
B21: 二代健保 (m) | C21: =總表!$AE$6 -> 0
B22: 自提勞退 (n) | C22: =總表!$AG$6 -> 0
A23: 應扣總款(B) | B23: k+l+m+n | C23: =總表!$AH$6 -> 2744
A24: 支領現金 | C24: =總表!$AJ$6 -> 0
A25: 實發薪資(C) | B25: 銀行薪轉金額 | C25: =總表!$AK$6 -> 54326
A26: 勞退 (D) | B26: 機構負擔勞退6% | C26: =總表!$AL$6 -> 3180
A27: 實得薪資 | C27: =C25+C26 -> 57506
A28: 備註

Sheet 113年12月(2)
A4: =總表!$A$7 -> 113年12月(2)
A5: =總表!$E$7 -> 居服員 | B5: =總表!$D$7 -> N0174 | C5: =總表!$F$7 -> 曾馨幼
A6: 項目(A1) | B6: 薪資/小時 (a) | C6: 200
B7: 工作加給/小時 (aa)
B8: 平日服務時數 (b)
B9: 本薪 (c)
B10: 平日加班加給/小時 (d) | C10: 66
B11: 平日加班時數 (e)
B12: 平日延長加班/假日(休息及國定) 加給/小時 (f) | C12: 200
B13: 延長加班+例假日服務時數 (g)
B14: 總加班費 (h)
B15: 津貼/小時 (i) | C15: 50
B16: 總津貼(50*總工作時數 ) (j)
A17: 獎金(A2) | B17: 113年第4季政策鼓勵獎金 | C17: =總表!$W$7 -> 15420
A18: 應發薪資(A) | B18: A1(c+h+j)+A2 | C18: =總表!$X$7 -> 15420
A19: 個人扣項 | B19: 勞保費() (k)
B20: 健保費() (l)
B21: 二代健保 (m)
B22: 自提勞退 (n)
A23: 應扣總款(B) | B23: k+l+m+n | C23: =總表!$AH$7 -> 0
A24: 支領現金 | C24: =總表!$AJ$7 -> 0
A25: 實發薪資(C) | B25: 銀行薪轉金額 | C25: =總表!$AK$7 -> 15420
A26: 勞退 (D) | B26: 機構負擔勞退6%
A27: 實得薪資 | C27: =C25+C26 -> 15420
A28: 備註 | B28: 每月碼別/次數/金額詳細及同天服務拆碼加減帳,請參考 AA碼季獎金 頁面

Sheet 114年1月
A4: =總表!$A$8 -> 114年1月
A5: =總表!$E$8 -> 居服員 | B5: =總表!$D$8 -> N0174 | C5: =總表!$F$8 -> 曾馨幼
A6: 項目(A1) | B6: 薪資/小時 (a) | C6: 200
B7: 工作加給/小時 (aa)
B8: 平日服務時數 (b) | C8: =總表!$O$8 -> 119.92
B9: 本薪 (c) | C9: =總表!$T$8 -> 23984
B10: 平日加班加給/小時 (d) | C10: 66
B11: 平日加班時數 (e) | C11: =總表!$P$8 -> 0
B12: 平日延長加班/假日(休息及國定) 加給/小時 (f) | C12: 200
B13: 延長加班+例假日服務時數 (g) | C13: =總表!$R$8 -> 38.75
B14: 總加班費 (h) | C14: =總表!$U$8 -> 15500
B15: 津貼/小時 (i) | C15: 50
B16: 總津貼(50*總工作時數 ) (j) | C16: =總表!$V$8 -> 7934
A17: 獎金(A2) | C17: =總表!$W$8 -> 0
A18: 應發薪資(A) | B18: A1(c+h+j)+A2 | C18: =總表!$X$8 -> 47418
A19: 個人扣項 | B19: 勞保費(45800) (k) | C19: =總表!$AA$8 -> 1145
B20: 健保費(53000) (l) | C20: =總表!$AC$8 -> 1644
B21: 二代健保 (m) | C21: =總表!$AE$8 -> 0
B22: 自提勞退 (n) | C22: =總表!$AG$8 -> 0
A23: 應扣總款(B) | B23: k+l+m+n | C23: =總表!$AH$8 -> 2789
A24: 支領現金 | C24: =總表!$AJ$8 -> 0
A25: 實發薪資(C) | B25: 銀行薪轉金額 | C25: =總表!$AK$8 -> 44629
A26: 勞退 (D) | B26: 機構負擔勞退6% | C26: =總表!$AL$8 -> 3180
A27: 實得薪資 | C27: =C25+C26 -> 47809
A28: 備註

Sheet 114年2月
A4: =總表!$A$9 -> 114年2月
A5: =總表!$E$9 -> 居服員 | B5: =總表!$D$9 -> N0174 | C5: =總表!$F$9 -> 曾馨幼
A6: 項目(A1) | B6: 薪資/小時 (a) | C6: 200
B7: 工作加給/小時 (aa)
B8: 平日服務時數 (b) | C8: =總表!$O$9 -> 148.33
B9: 本薪 (c) | C9: =總表!$T$9 -> 29666
B10: 平日加班加給/小時 (d) | C10: 66
B11: 平日加班時數 (e) | C11: =總表!$P$9 -> 0.33
B12: 平日延長加班/假日(休息及國定) 加給/小時 (f) | C12: 200
B13: 延長加班+例假日服務時數 (g) | C13: =總表!$R$9 -> 36.5
B14: 總加班費 (h) | C14: =總表!$U$9 -> 14688
B15: 津貼/小時 (i) | C15: 50
B16: 總津貼(50*總工作時數 ) (j) | C16: =總表!$V$9 -> 9258
A17: 獎金(A2) | C17: =總表!$W$9 -> 0
A18: 應發薪資(A) | B18: A1(c+h+j)+A2 | C18: =總表!$X$9 -> 53612
A19: 個人扣項 | B19: 勞保費(45800) (k) | C19: =總表!$AA$9 -> 1145
B20: 健保費(53000) (l) | C20: =總表!$AC$9 -> 1644
B21: 二代健保 (m) | C21: =總表!$AE$9 -> 0
B22: 自提勞退 (n) | C22: =總表!$AG$9 -> 0
A23: 應扣總款(B) | B23: k+l+m+n | C23: =總表!$AH$9 -> 2789
A24: 支領現金 | C24: =總表!$AJ$9 -> 0
A25: 實發薪資(C) | B25: 銀行薪轉金額 | C25: =總表!$AK$9 -> 50823
A26: 勞退 (D) | B26: 機構負擔勞退6% | C26: =總表!$AL$9 -> 3180
A27: 實得薪資 | C27: =C25+C26 -> 54003
A28: 備註 | B28: 1.機構調整勞/健保及職災/勞退逕調投保級距, 以113年10~12月平均薪資為本之季調, 已於114/02/01生效.

Sheet 114年3月
A4: =總表!$A$10 -> 114年3月
A5: =總表!$E$10 -> 居服員 | B5: =總表!$D$10 -> N0174 | C5: =總表!$F$10 -> 曾馨幼
A6: 項目(A1) | B6: 薪資/小時 (a) | C6: 200
B7: 工作加給/小時 (aa)
B8: 平日服務時數 (b) | C8: =總表!$O$10 -> 160.33
B9: 本薪 (c) | C9: =總表!$T$10 -> 32066
B10: 平日加班加給/小時 (d) | C10: 66
B11: 平日加班時數 (e) | C11: =總表!$P$10 -> 1.67
B12: 平日延長加班/假日(休息及國定) 加給/小時 (f) | C12: 200
B13: 延長加班+例假日服務時數 (g) | C13: =總表!$R$10 -> 28
B14: 總加班費 (h) | C14: =總表!$U$10 -> 11702
B15: 津貼/小時 (i) | C15: 50
B16: 總津貼(50*總工作時數 ) (j) | C16: =總表!$V$10 -> 9500
A17: 獎金(A2) | C17: =總表!$W$10 -> 0
A18: 應發薪資(A) | B18: A1(c+h+j)+A2 | C18: =總表!$X$10 -> 53268
A19: 個人扣項 | B19: 勞保費(45800) (k) | C19: =總表!$AA$10 -> 1145
B20: 健保費(53000) (l) | C20: =總表!$AC$10 -> 1644
B21: 二代健保 (m) | C21: =總表!$AE$10 -> 0
B22: 自提勞退 (n) | C22: =總表!$AG$10 -> 0
A23: 應扣總款(B) | B23: k+l+m+n | C23: =總表!$AH$10 -> 2789
A24: 支領現金 | C24: =總表!$AJ$10 -> 0
A25: 實發薪資(C) | B25: 銀行薪轉金額 | C25: =總表!$AK$10 -> 50479
A26: 勞退 (D) | B26: 機構負擔勞退6% | C26: =總表!$AL$10 -> 3180
A27: 實得薪資 | C27: =C25+C26 -> 53659
A28: 備註

Sheet 114年3月(2)
A4: =總表!$A$11 -> 114年3月(2)
A5: =總表!$E$11 -> 居服員 | B5: =總表!$D$11 -> N0174 | C5: =總表!$F$11 -> 曾馨幼
A6: 項目(A1) | B6: 薪資/小時 (a) | C6: 200
B7: 工作加給/小時 (aa)
B8: 平日服務時數 (b)
B9: 本薪 (c)
B10: 平日加班加給/小時 (d) | C10: 66
B11: 平日加班時數 (e)
B12: 平日延長加班/假日(休息及國定) 加給/小時 (f) | C12: 200
B13: 延長加班+例假日服務時數 (g)
B14: 總加班費 (h)
B15: 津貼/小時 (i) | C15: 50
B16: 總津貼(50*總工作時數 ) (j)
A17: 獎金(A2) | B17: 114年第1季政策鼓勵獎金 | C17: =總表!$W$11 -> 13470
A18: 應發薪資(A) | B18: A1(c+h+j)+A2 | C18: =總表!$X$11 -> 13470
A19: 個人扣項 | B19: 勞保費() (k)
B20: 健保費() (l)
B21: 二代健保 (m)
B22: 自提勞退 (n)
A23: 應扣總款(B) | B23: k+l+m+n | C23: =總表!$AH$11 -> 0
A24: 支領現金 | C24: =總表!$AJ$11 -> 0
A25: 實發薪資(C) | B25: 銀行薪轉金額 | C25: =總表!$AK$11 -> 13470
A26: 勞退 (D) | B26: 機構負擔勞退6%
A27: 實得薪資 | C27: =C25+C26 -> 13470
A28: 備註 | B28: 每月碼別/次數/金額詳細及同天服務拆碼加減帳,請參考 AA碼季獎金 頁面

Sheet 114年4月
A4: =總表!$A$12 -> 114年4月
A5: =總表!$E$12 -> 居服員 | B5: =總表!$D$12 -> N0174 | C5: =總表!$F$12 -> 曾馨幼
A6: 項目(A1) | B6: 薪資/小時 (a) | C6: 200
B7: 工作加給/小時 (aa)
B8: 平日服務時數 (b) | C8: =總表!$O$12 -> 139.83
B9: 本薪 (c) | C9: =總表!$T$12 -> 27966
B10: 平日加班加給/小時 (d) | C10: 66
B11: 平日加班時數 (e) | C11: =總表!$P$12 -> 0
B12: 平日延長加班/假日(休息及國定) 加給/小時 (f) | C12: 200
B13: 延長加班+例假日服務時數 (g) | C13: =總表!$R$12 -> 48
B14: 總加班費 (h) | C14: =總表!$U$12 -> 19200
B15: 津貼/小時 (i) | C15: 50
B16: 總津貼(50*總工作時數 ) (j) | C16: =總表!$V$12 -> 9392
A17: 獎金(A2) | C17: =總表!$W$12 -> 0
A18: 應發薪資(A) | B18: A1(c+h+j)+A2 | C18: =總表!$X$12 -> 56558
A19: 個人扣項 | B19: 勞保費(45800) (k) | C19: =總表!$AA$12 -> 1145
B20: 健保費(53000) (l) | C20: =總表!$AC$12 -> 1644
B21: 二代健保 (m) | C21: =總表!$AE$12 -> 0
B22: 自提勞退 (n) | C22: =總表!$AG$12 -> 0
A23: 應扣總款(B) | B23: k+l+m+n | C23: =總表!$AH$12 -> 2789
A24: 支領現金 | C24: =總表!$AJ$12 -> 0
A25: 實發薪資(C) | B25: 銀行薪轉金額 | C25: =總表!$AK$12 -> 53769
A26: 勞退 (D) | B26: 機構負擔勞退6% | C26: =總表!$AL$12 -> 3180
A27: 實得薪資 | C27: =C25+C26 -> 56949
A28: 備註

Sheet 114年5月
A4: =總表!$A$13 -> 114年5月
A5: =總表!$E$13 -> 居服員 | B5: =總表!$D$13 -> N0174 | C5: =總表!$F$13 -> 曾馨幼
A6: 項目(A1) | B6: 薪資/小時 (a) | C6: 200
B7: 工作加給/小時 (aa)
B8: 平日服務時數 (b) | C8: =總表!$O$13 -> 116.83
B9: 本薪 (c) | C9: =總表!$T$13 -> 23366
B10: 平日加班加給/小時 (d) | C10: 66
B11: 平日加班時數 (e) | C11: =總表!$P$13 -> 0
B12: 平日延長加班/假日(休息及國定) 加給/小時 (f) | C12: 200
B13: 延長加班+例假日服務時數 (g) | C13: =總表!$R$13 -> 48.83
B14: 總加班費 (h) | C14: =總表!$U$13 -> 19532
B15: 津貼/小時 (i) | C15: 50
B16: 總津貼(50*總工作時數 ) (j) | C16: =總表!$V$13 -> 8283
A17: 獎金(A2) | C17: =總表!$W$13 -> 0
A18: 應發薪資(A) | B18: A1(c+h+j)+A2 | C18: =總表!$X$13 -> 51181
A19: 個人扣項 | B19: 勞保費(45800) (k) | C19: =總表!$AA$13 -> 1145
B20: 健保費(53000) (l) | C20: =總表!$AC$13 -> 1644
B21: 二代健保 (m) | C21: =總表!$AE$13 -> 0
B22: 自提勞退 (n) | C22: =總表!$AG$13 -> 0
A23: 應扣總款(B) | B23: k+l+m+n | C23: =總表!$AH$13 -> 2789
A24: 支領現金 | C24: =總表!$AJ$13 -> 0
A25: 實發薪資(C) | B25: 銀行薪轉金額 | C25: =總表!$AK$13 -> 48392
A26: 勞退 (D) | B26: 機構負擔勞退6% | C26: =總表!$AL$13 -> 3180
A27: 實得薪資 | C27: =C25+C26 -> 51572
A28: 備註 | B28: 1.機構調整勞/健保及職災/勞退逕調投保級距, 以114年1~3月平均薪資為本之季調, 已於114/05/01生效. 2.補發五一假日薪資計算為平日薪資差額：7.82H*$200=$1564元 6/25己發 $49618 於6/27補發$1564元

Sheet 114年6月
A4: =總表!$A$14 -> 114年6月
A5: =總表!$E$14 -> 居服員 | B5: =總表!$D$14 -> N0174 | C5: =總表!$F$14 -> 曾馨幼
A6: 項目(A1) | B6: 薪資/小時 (a) | C6: 200
B7: 工作加給/小時 (aa)
B8: 平日服務時數 (b) | C8: =總表!$O$14 -> 152.83
B9: 本薪 (c) | C9: =總表!$T$14 -> 30566
B10: 平日加班加給/小時 (d) | C10: 66
B11: 平日加班時數 (e) | C11: =總表!$P$14 -> 0.83
B12: 平日延長加班/假日(休息及國定) 加給/小時 (f) | C12: 200
B13: 延長加班+例假日服務時數 (g) | C13: =總表!$R$14 -> 43.83
B14: 總加班費 (h) | C14: =總表!$U$14 -> 17753
B15: 津貼/小時 (i) | C15: 50
B16: 總津貼(50*總工作時數 ) (j) | C16: =總表!$V$14 -> 9875
A17: 獎金(A2) | C17: =總表!$W$14 -> 0
A18: 應發薪資(A) | B18: A1(c+h+j)+A2 | C18: =總表!$X$14 -> 58194
A19: 個人扣項 | B19: 勞保費(45800) (k) | C19: =總表!$AA$14 -> 1145
B20: 健保費(53000) (l) | C20: =總表!$AC$14 -> 1644
B21: 二代健保 (m) | C21: =總表!$AE$14 -> 0
B22: 自提勞退 (n) | C22: =總表!$AG$14 -> 0
A23: 應扣總款(B) | B23: k+l+m+n | C23: =總表!$AH$14 -> 2789
A24: 支領現金 | C24: =總表!$AJ$14 -> 0
A25: 實發薪資(C) | B25: 銀行薪轉金額 | C25: =總表!$AK$14 -> 55405
A26: 勞退 (D) | B26: 機構負擔勞退6% | C26: =總表!$AL$14 -> 3180
A27: 實得薪資 | C27: =C25+C26 -> 58585
A28: 備註

Sheet 114年6月(2)
A4: =總表!$A$15 -> 114年6月(2)
A5: =總表!$E$15 -> 居服員 | B5: =總表!$D$15 -> N0174 | C5: =總表!$F$15 -> 曾馨幼
A6: 項目(A1) | B6: 薪資/小時 (a) | C6: 200
B7: 工作加給/小時 (aa)
B8: 平日服務時數 (b)
B9: 本薪 (c)
B10: 平日加班加給/小時 (d) | C10: 66
B11: 平日加班時數 (e)
B12: 平日延長加班/假日(休息及國定) 加給/小時 (f) | C12: 200
B13: 延長加班+例假日服務時數 (g)
B14: 總加班費 (h)
B15: 津貼/小時 (i) | C15: 50
B16: 總津貼(50*總工作時數 ) (j)
A17: 獎金(A2) | B17: 114年第2季政策鼓勵獎金 | C17: =總表!$W$15 -> 11653
A18: 應發薪資(A) | B18: A1(c+h+j)+A2 | C18: =總表!$X$15 -> 11653
A19: 個人扣項 | B19: 勞保費() (k)
B20: 健保費() (l)
B21: 二代健保 (m)
B22: 自提勞退 (n)
A23: 應扣總款(B) | B23: k+l+m+n | C23: =總表!$AH$15 -> 0
A24: 支領現金 | C24: =總表!$AJ$15 -> 0
A25: 實發薪資(C) | B25: 銀行薪轉金額 | C25: =總表!$AK$15 -> 11653
A26: 勞退 (D) | B26: 機構負擔勞退6%
A27: 實得薪資 | C27: =C25+C26 -> 11653
A28: 備註 | B28: 每月碼別/次數/金額詳細及同天服務拆碼加減帳,請參考 AA碼季獎金 頁面

Sheet 114年7月
A4: =總表!$A$16 -> 114年7月
A5: =總表!$E$16 -> 居服員 | B5: =總表!$D$16 -> N0174 | C5: =總表!$F$16 -> 曾馨幼
A6: 項目(A1) | B6: 薪資/小時 (a) | C6: 200
B7: 工作加給/小時 (aa)
B8: 平日服務時數 (b) | C8: =總表!$O$16 -> 168.33
B9: 本薪 (c) | C9: =總表!$T$16 -> 33666
B10: 平日加班加給/小時 (d) | C10: 66
B11: 平日加班時數 (e) | C11: =總表!$P$16 -> 0.33
B12: 平日延長加班/假日(休息及國定) 加給/小時 (f) | C12: 200
B13: 延長加班+例假日服務時數 (g) | C13: =總表!$R$16 -> 24
B14: 總加班費 (h) | C14: =總表!$U$16 -> 9688
B15: 津貼/小時 (i) | C15: 50
B16: 總津貼(50*總工作時數 ) (j) | C16: =總表!$V$16 -> 9633
A17: 獎金(A2) | C17: =總表!$W$16 -> 0
A18: 應發薪資(A) | B18: A1(c+h+j)+A2 | C18: =總表!$X$16 -> 52987
A19: 個人扣項 | B19: 勞保費(45800) (k) | C19: =總表!$AA$16 -> 1145
B20: 健保費(53000) (l) | C20: =總表!$AC$16 -> 1644
B21: 二代健保 (m) | C21: =總表!$AE$16 -> 0
B22: 自提勞退 (n) | C22: =總表!$AG$16 -> 0
A23: 應扣總款(B) | B23: k+l+m+n | C23: =總表!$AH$16 -> 2789
A24: 支領現金 | C24: =總表!$AJ$16 -> 0
A25: 實發薪資(C) | B25: 銀行薪轉金額 | C25: =總表!$AK$16 -> 50198
A26: 勞退 (D) | B26: 機構負擔勞退6% | C26: =總表!$AL$16 -> 3180
A27: 實得薪資 | C27: =C25+C26 -> 53378
A28: 備註

Sheet 114年8月
A4: =總表!$A$17 -> 114年8月
A5: =總表!$E$17 -> 居服員 | B5: =總表!$D$17 -> N0174 | C5: =總表!$F$17 -> 曾馨幼
A6: 項目(A1) | B6: 薪資/小時 (a) | C6: 200
B7: 工作加給/小時 (aa)
B8: 平日服務時數 (b) | C8: =總表!$O$17 -> 153
B9: 本薪 (c) | C9: =總表!$T$17 -> 30600
B10: 平日加班加給/小時 (d) | C10: 66
B11: 平日加班時數 (e) | C11: =總表!$P$17 -> 0
B12: 平日延長加班/假日(休息及國定) 加給/小時 (f) | C12: 200
B13: 延長加班+例假日服務時數 (g) | C13: =總表!$R$17 -> 30.5
B14: 總加班費 (h) | C14: =總表!$U$17 -> 12200
B15: 津貼/小時 (i) | C15: 50
B16: 總津貼(50*總工作時數 ) (j) | C16: =總表!$V$17 -> 9175
A17: 獎金(A2) | C17: =總表!$W$17 -> 0
A18: 應發薪資(A) | B18: A1(c+h+j)+A2 | C18: =總表!$X$17 -> 51975
A19: 個人扣項 | B19: 勞保費(45800) (k) | C19: =總表!$AA$17 -> 1145
B20: 健保費(55400) (l) | C20: =總表!$AC$17 -> 1718
B21: 二代健保 (m) | C21: =總表!$AE$17 -> 0
B22: 自提勞退 (n) | C22: =總表!$AG$17 -> 0
A23: 應扣總款(B) | B23: k+l+m+n | C23: =總表!$AH$17 -> 2863
A24: 支領現金 | C24: =總表!$AJ$17 -> 0
A25: 實發薪資(C) | B25: 銀行薪轉金額 | C25: =總表!$AK$17 -> 49112
A26: 勞退 (D) | B26: 機構負擔勞退6% | C26: =總表!$AL$17 -> 3324
A27: 實得薪資 | C27: =C25+C26 -> 52436
A28: 備註 | B28: 機構調整勞/健保及職災/勞退逕調投保級距, 以114年4~6月平均薪資為本之季調, 已於114/08/01生效.

Sheet 114年9月
A4: =總表!$A$18 -> 114年9月
A5: =總表!$E$18 -> 居服員 | B5: =總表!$D$18 -> N0174 | C5: =總表!$F$18 -> 曾馨幼
A6: 項目(A1) | B6: 薪資/小時 (a) | C6: 200
B7: 工作加給/小時 (aa)
B8: 平日服務時數 (b) | C8: =總表!$O$18 -> 124
B9: 本薪 (c) | C9: =總表!$T$18 -> 24800
B10: 平日加班加給/小時 (d) | C10: 66
B11: 平日加班時數 (e) | C11: =總表!$P$18 -> 0
B12: 平日延長加班/假日(休息及國定) 加給/小時 (f) | C12: 200
B13: 延長加班+例假日服務時數 (g) | C13: =總表!$R$18 -> 30
B14: 總加班費 (h) | C14: =總表!$U$18 -> 12000
B15: 津貼/小時 (i) | C15: 50
B16: 總津貼(50*總工作時數 ) (j) | C16: =總表!$V$18 -> 7700
A17: 獎金(A2) | C17: =總表!$W$18 -> 0
A18: 應發薪資(A) | B18: A1(c+h+j)+A2 | C18: =總表!$X$18 -> 44500
A19: 個人扣項 | B19: 勞保費(45800) (k) | C19: =總表!$AA$18 -> 1145
B20: 健保費(55400) (l) | C20: =總表!$AC$18 -> 1718
B21: 二代健保 (m) | C21: =總表!$AE$18 -> 0
B22: 自提勞退 (n) | C22: =總表!$AG$18 -> 0
A23: 應扣總款(B) | B23: k+l+m+n | C23: =總表!$AH$18 -> 2863
A24: 支領現金 | C24: =總表!$AJ$18 -> 0
A25: 實發薪資(C) | B25: 銀行薪轉金額 | C25: =總表!$AK$18 -> 41637
A26: 勞退 (D) | B26: 機構負擔勞退6% | C26: =總表!$AL$18 -> 3324
A27: 實得薪資 | C27: =C25+C26 -> 44961
A28: 備註

Sheet 114年9月(2)
A4: =總表!$A$19 -> 114年9月(2)
A5: =總表!$E$19 -> 居服員 | B5: =總表!$D$19 -> N0174 | C5: =總表!$F$19 -> 曾馨幼
A6: 項目(A1) | B6: 薪資/小時 (a) | C6: 200
B7: 工作加給/小時 (aa)
B8: 平日服務時數 (b)
B9: 本薪 (c)
B10: 平日加班加給/小時 (d) | C10: 66
B11: 平日加班時數 (e)
B12: 平日延長加班/假日(休息及國定) 加給/小時 (f) | C12: 200
B13: 延長加班+例假日服務時數 (g)
B14: 總加班費 (h)
B15: 津貼/小時 (i) | C15: 50
B16: 總津貼(50*總工作時數 ) (j)
A17: 獎金(A2) | B17: 114年第3季政策鼓勵獎金 | C17: =總表!$W$19 -> 6610
A18: 應發薪資(A) | B18: A1(c+h+j)+A2 | C18: =總表!$X$19 -> 6610
A19: 個人扣項 | B19: 勞保費() (k)
B20: 健保費() (l)
B21: 二代健保 (m)
B22: 自提勞退 (n)
A23: 應扣總款(B) | B23: k+l+m+n | C23: =總表!$AH$19 -> 0
A24: 支領現金 | C24: =總表!$AJ$19 -> 0
A25: 實發薪資(C) | B25: 銀行薪轉金額 | C25: =總表!$AK$19 -> 6610
A26: 勞退 (D) | B26: 機構負擔勞退6%
A27: 實得薪資 | C27: =C25+C26 -> 6610
A28: 備註 | B28: 每月碼別/次數/金額詳細及同天服務拆碼加減帳,請參考 AA碼季獎金 頁面

Sheet 114年10月
A4: =總表!$A$20 -> 114年10月
A5: =總表!$E$20 -> 居服員 | B5: =總表!$D$20 -> N0174 | C5: =總表!$F$20 -> 曾馨幼
A6: 項目(A1) | B6: 薪資/小時 (a) | C6: 200
B7: 工作加給/小時 (aa)
B8: 平日服務時數 (b) | C8: =總表!$O$20 -> 117.67
B9: 本薪 (c) | C9: =總表!$T$20 -> 23534
B10: 平日加班加給/小時 (d) | C10: 66
B11: 平日加班時數 (e) | C11: =總表!$P$20 -> 0
B12: 平日延長加班/假日(休息及國定) 加給/小時 (f) | C12: 200
B13: 延長加班+例假日服務時數 (g) | C13: =總表!$R$20 -> 38.33
B14: 總加班費 (h) | C14: =總表!$U$20 -> 15332
B15: 津貼/小時 (i) | C15: 50
B16: 總津貼(50*總工作時數 ) (j) | C16: =總表!$V$20 -> 7800
A17: 獎金(A2) | C17: =總表!$W$20 -> 0
A18: 應發薪資(A) | B18: A1(c+h+j)+A2 | C18: =總表!$X$20 -> 46666
A19: 個人扣項 | B19: 勞保費(45800) (k) | C19: =總表!$AA$20 -> 1145
B20: 健保費(55400) (l) | C20: =總表!$AC$20 -> 1718
B21: 二代健保 (m) | C21: =總表!$AE$20 -> 0
B22: 自提勞退 (n) | C22: =總表!$AG$20 -> 0
A23: 應扣總款(B) | B23: k+l+m+n | C23: =總表!$AH$20 -> 2863
A24: 支領現金 | C24: =總表!$AJ$20 -> 0
A25: 實發薪資(C) | B25: 銀行薪轉金額 | C25: =總表!$AK$20 -> 43803
A26: 勞退 (D) | B26: 機構負擔勞退6% | C26: =總表!$AL$20 -> 3324
A27: 實得薪資 | C27: =C25+C26 -> 47127
A28: 備註

Sheet 114年11月
A4: =總表!$A$21 -> 114年11月
A5: =總表!$E$21 -> 居服員 | B5: =總表!$D$21 -> N0174 | C5: =總表!$F$21 -> 曾馨幼
A6: 項目(A1) | B6: 薪資/小時 (a) | C6: 200
B7: 工作加給/小時 (aa)
B8: 平日服務時數 (b) | C8: =總表!$O$21 -> 116.67
B9: 本薪 (c) | C9: =總表!$T$21 -> 23334
B10: 平日加班加給/小時 (d) | C10: 66
B11: 平日加班時數 (e) | C11: =總表!$P$21 -> 0
B12: 平日延長加班/假日(休息及國定) 加給/小時 (f) | C12: 200
B13: 延長加班+例假日服務時數 (g) | C13: =總表!$R$21 -> 24
B14: 總加班費 (h) | C14: =總表!$U$21 -> 9600
B15: 津貼/小時 (i) | C15: 50
B16: 總津貼(50*總工作時數 ) (j) | C16: =總表!$V$21 -> 7034
A17: 獎金(A2) | C17: =總表!$W$21 -> 0
A18: 應發薪資(A) | B18: A1(c+h+j)+A2 | C18: =總表!$X$21 -> 39968
A19: 個人扣項 | B19: 勞保費(45800) (k) | C19: =總表!$AA$21 -> 1145
B20: 健保費(50600) (l) | C20: =總表!$AC$21 -> 1570
B21: 二代健保 (m) | C21: =總表!$AE$21 -> 0
B22: 自提勞退 (n) | C22: =總表!$AG$21 -> 0
A23: 應扣總款(B) | B23: k+l+m+n | C23: =總表!$AH$21 -> 2715
A24: 支領現金 | C24: =總表!$AJ$21 -> 0
A25: 實發薪資(C) | B25: 銀行薪轉金額 | C25: =總表!$AK$21 -> 37253
A26: 勞退 (D) | B26: 機構負擔勞退6% | C26: =總表!$AL$21 -> 3036
A27: 實得薪資 | C27: =C25+C26 -> 40289
A28: 備註 | B28: 1.機構調整勞/健保及職災/勞退逕調投保級距, 以114年7~9月平均薪資為本之季調, 已於114/11/01生效.

Sheet 114年12月
A4: =總表!$A$22 -> 114年12月
A5: =總表!$E$22 -> 居服員 | B5: =總表!$D$22 -> N0174 | C5: =總表!$F$22 -> 曾馨幼
A6: 項目(A1) | B6: 薪資/小時 (a) | C6: 200
B7: 工作加給/小時 (aa)
B8: 平日服務時數 (b) | C8: =總表!$O$22 -> 111.5
B9: 本薪 (c) | C9: =總表!$T$22 -> 22300
B10: 平日加班加給/小時 (d) | C10: 66
B11: 平日加班時數 (e) | C11: =總表!$P$22 -> 0
B12: 平日延長加班/假日(休息及國定) 加給/小時 (f) | C12: 200
B13: 延長加班+例假日服務時數 (g) | C13: =總表!$R$22 -> 42
B14: 總加班費 (h) | C14: =總表!$U$22 -> 16800
B15: 津貼/小時 (i) | C15: 50
B16: 總津貼(50*總工作時數 ) (j) | C16: =總表!$V$22 -> 7675
A17: 獎金(A2) | C17: =總表!$W$22 -> 0
A18: 應發薪資(A) | B18: A1(c+h+j)+A2 | C18: =總表!$X$22 -> 46775
A19: 個人扣項 | B19: 勞保費(45800) (k) | C19: =總表!$AA$22 -> 1145
B20: 健保費(50600) (l) | C20: =總表!$AC$22 -> 1570
B21: 二代健保 (m) | C21: =總表!$AE$22 -> 0
B22: 自提勞退 (n) | C22: =總表!$AG$22 -> 0
A23: 應扣總款(B) | B23: k+l+m+n | C23: =總表!$AH$22 -> 2715
A24: 支領現金 | C24: =總表!$AJ$22 -> 0
A25: 實發薪資(C) | B25: 銀行薪轉金額 | C25: =總表!$AK$22 -> 44060
A26: 勞退 (D) | B26: 機構負擔勞退6% | C26: =總表!$AL$22 -> 3036
A27: 實得薪資 | C27: =C25+C26 -> 47096
A28: 備註

Sheet 總表
A4: 基本資料 | J4: 服務所得 | Y4: 勞健保費 | AI4: X-AH | AK4: AI-AJ
A5: 年月 | B5: 正/兼職 | C5: 身分證字號 | D5: 員工編號 | E5: 職稱 | F5: 姓名 | G5: 薪制 | H5: 銀行帳號 | I5: 連絡電話 | J5: 時薪 | K5: 平日工作加給 | L5: 平日加班加給 /B碼拆帳比 /督導常日拆帳比 | M5: 延常例價國定日加給 /A碼拆障比 /督導加班及假日拆帳比 | N5: 津貼 | O5: 平日時數 | P5: 平日加班時數 | Q5: 平日加班時數超過10小時 /總工時累進加給比例 | R5: 例假日時數 | S5: 總工作時數 | T5: 本薪 /服務B碼營業額 | U5: 總加班費 /政策鼓勵A碼獎金 | V5: 總津貼 /服務B碼所得 | W5: 獎金 /政策A碼獎金所得 | X5: 應發薪資 | Y5: 加(退)保日 | Z5: 勞保投保金額 | AA5: 勞保費 | AB5: 健保投保金額 | AC5: 健保費 | AD5: 加保人數 | AE5: 二代健保 補充保費 | AF5: 補充保費計算 | AG5: 自提勞退 / 銀行債務 | AH5: 應扣金額 | AI5: 應付薪資 | AJ5: 支領現金 | AK5: 薪轉金額 | AL5: 公司負擔勞退
A6: 113年12月 | B6: 正 | C6: F224490326 | D6: N0174 | E6: 居服員 | F6: 曾馨幼 | G6: 時薪 | H6: 699513899681 | I6: 0922297795 | J6: 200 | L6: 66 | M6: 200 | N6: 50 | O6: 167.17 | P6: 0.17 | Q6: 0 | R6: 33.83 | S6: 201.17 | T6: 33434 | U6: 13577 | V6: 10059 | W6: 0 | X6: 57070 | Y6: 1130801 | Z6: 45800 | AA6: 1100 | AB6: 53000 | AC6: 1644 | AD6: 1 | AE6: 0 | AF6: 86 | AG6: 0 | AH6: 2744 | AI6: 54326 | AJ6: 0 | AK6: 54326 | AL6: 3180 | BT6: 劉小萍 | BV6: 0 | BX6: 劉小萍 | BZ6: 54 | CB6: 卓美鳳 | CC6: 47995 | CD6: 17918.8 | CF6: 卓美鳳
A7: 113年12月(2) | B7: 正 | C7: F224490326 | D7: N0174 | E7: 居服員 | F7: 曾馨幼 | G7: 時薪 | H7: 699513899681 | I7: 0922297795 | J7: 200 | L7: 66 | M7: 200 | N7: 50 | W7: 15420 | X7: 15420 | AI7: 15420 | AJ7: 0 | AK7: 15420
A8: 114年1月 | B8: 正 | C8: F224490326 | D8: N0174 | E8: 居服員 | F8: 曾馨幼 | G8: 時薪 | H8: 699513899681 | I8: 0922297795 | J8: 200 | L8: 66 | M8: 200 | N8: 50 | O8: 119.92 | P8: 0 | Q8: 0 | R8: 38.75 | S8: 158.67 | T8: 23984 | U8: 15500 | V8: 7934 | W8: 0 | X8: 47418 | Y8: 1130801 | Z8: 45800 | AA8: 1145 | AB8: 53000 | AC8: 1644 | AD8: 1 | AE8: 0 | AF8: -118 | AG8: 0 | AH8: 2789 | AI8: 44629 | AJ8: 0 | AK8: 44629 | AL8: 3180 | BT8: 廖麒翔 | BV8: 0 | BX8: 廖麒翔 | BZ8: 56 | CB8: 周宥樺 | CC8: 500 | CD8: 200 | CF8: 周宥樺
A9: 114年2月 | B9: 正 | C9: F224490326 | D9: N0174 | E9: 居服員 | F9: 曾馨幼 | G9: 時薪 | H9: 699513899681 | I9: 0922297795 | J9: 200 | L9: 66 | M9: 200 | N9: 50 | O9: 148.33 | P9: 0.33 | Q9: 0 | R9: 36.5 | S9: 185.16 | T9: 29666 | U9: 14688 | V9: 9258 | W9: 0 | X9: 53612 | Y9: 1130801 | Z9: 45800 | AA9: 1145 | AB9: 53000 | AC9: 1644 | AD9: 1 | AE9: 0 | AF9: 13 | AG9: 0 | AH9: 2789 | AI9: 50823 | AJ9: 0 | AK9: 50823 | AL9: 3180 | BT9: 鄭聖諺 | BV9: 0 | BX9: 鄭聖諺 | BZ9: 57 | CB9: 黃月娥 | CC9: 50085 | CD9: 7310 | CF9: 黃月娥
A10: 114年3月 | B10: 正 | C10: F224490326 | D10: N0174 | E10: 居服員 | F10: 曾馨幼 | G10: 時薪 | H10: 699513899681 | I10: 0922297795 | J10: 200 | L10: 66 | M10: 200 | N10: 50 | O10: 160.33 | P10: 1.67 | Q10: 0.43 | R10: 28 | S10: 190 | T10: 32066 | U10: 11702 | V10: 9500 | W10: 0 | X10: 53268 | Y10: 113/08/01 | Z10: 45800 | AA10: 1145 | AB10: 53000 | AC10: 1644 | AD10: 1 | AE10: 0 | AF10: 6 | AG10: 0 | AH10: 2789 | AI10: 50479 | AJ10: 0 | AK10: 50479 | AL10: 3180 | BT10: 連曉琪 | BV10: 0 | BX10: 連曉琪 | BZ10: 59 | CB10: 周宥樺 | CC10: 3025 | CD10: 0 | CF10: 周宥樺
A11: 114年3月(2) | B11: 正 | C11: F224490326 | D11: N0174 | E11: 居服員 | F11: 曾馨幼 | G11: 時薪 | H11: 699513899681 | I11: 0922297795 | J11: 200 | L11: 66 | M11: 200 | N11: 50 | W11: 13470 | X11: 13470 | AI11: 13470 | AJ11: 0 | AK11: 13470
A12: 114年4月 | B12: 正 | C12: F224490326 | D12: N0174 | E12: 居服員 | F12: 曾馨幼 | G12: 時薪 | H12: 699513899681 | I12: 0922297795 | J12: 200 | L12: 66 | M12: 200 | N12: 50 | O12: 139.83 | P12: 0 | Q12: 0 | R12: 48 | S12: 187.83 | T12: 27966 | U12: 19200 | V12: 9392 | W12: 0 | X12: 56558 | Y12: 1130801 | Z12: 45800 | AA12: 1145 | AB12: 53000 | AC12: 1644 | AD12: 1 | AE12: 0 | AF12: 75 | AG12: 0 | AH12: 2789 | AI12: 53769 | AJ12: 0 | AK12: 53769 | AL12: 3180 | BT12: 余建美 | BV12: 0 | BX12: 余建美 | BZ12: 56 | CB12: 黃月娥 | CC12: 55945 | CD12: 11760 | CF12: 黃月娥
A13: 114年5月 | B13: 正 | C13: F224490326 | D13: N0174 | E13: 居服員 | F13: 曾馨幼 | G13: 時薪 | H13: 699513899681 | I13: 0922297795 | J13: 200 | L13: 66 | M13: 200 | N13: 50 | O13: 116.83 | P13: 0 | Q13: 0 | R13: 48.83 | S13: 165.66 | T13: 23366 | U13: 19532 | V13: 8283 | W13: 0 | X13: 51181 | Y13: 1130801 | Z13: 45800 | AA13: 1145 | AB13: 53000 | AC13: 1644 | AD13: 1 | AE13: 0 | AF13: -38 | AG13: 0 | AH13: 2789 | AI13: 48392 | AJ13: 0 | AK13: 48392 | AL13: 3180 | BT13: 吳虹儒 | BV13: 0 | BX13: 吳虹儒 | BZ13: 56 | CB13: 王麗雯 | CC13: 46070 | CD13: 28412.8 | CF13: 王麗雯
A14: 114年6月 | B14: 正 | C14: F224490326 | D14: N0174 | E14: 居服員 | F14: 曾馨幼 | G14: 時薪 | H14: 699513899681 | I14: 0922297795 | J14: 200 | L14: 66 | M14: 200 | N14: 50 | O14: 152.83 | P14: 0.83 | Q14: 0 | R14: 43.83 | S14: 197.49 | T14: 30566 | U14: 17753 | V14: 9875 | W14: 0 | X14: 58194 | Y14: 113/08/01 | Z14: 45800 | AA14: 1145 | AB14: 53000 | AC14: 1644 | AD14: 1 | AE14: 0 | AF14: 110 | AG14: 0 | AH14: 2789 | AI14: 55405 | AJ14: 0 | AK14: 55405 | AL14: 3180 | BT14: 劉嘉琳 | BV14: 0 | BX14: 劉嘉琳 | BZ14: 57 | CB14: 楊麗芹 | CC14: 59655 | CD14: 13400 | CF14: 楊麗芹
A15: 114年6月(2) | B15: 正 | C15: F224490326 | D15: N0174 | E15: 居服員 | F15: 曾馨幼 | G15: 時薪 | H15: 699513899681 | I15: 0922297795 | J15: 200 | L15: 66 | M15: 200 | N15: 50 | W15: 11653 | X15: 11653 | AI15: 11653 | AJ15: 0 | AK15: 11653
A16: 114年7月 | B16: 正 | C16: F224490326 | D16: N0174 | E16: 居服員 | F16: 曾馨幼 | G16: 時薪 | H16: 699513899681 | I16: 0922297795 | J16: 200 | L16: 66 | M16: 200 | N16: 50 | O16: 168.33 | P16: 0.33 | Q16: 0 | R16: 24 | S16: 192.66 | T16: 33666 | U16: 9688 | V16: 9633 | W16: 0 | X16: 52987 | Y16: 113/08/01 | Z16: 45800 | AA16: 1145 | AB16: 53000 | AC16: 1644 | AD16: 1 | AE16: 0 | AF16: 0 | AG16: 0 | AH16: 2789 | AI16: 50198 | AJ16: 0 | AK16: 50198 | AL16: 3180 | BT16: 王沛慈 | BV16: 0 | BX16: 王沛慈 | BZ16: 57 | CB16: 楊麗芹 | CC16: 64075 | CD16: 13900 | CF16: 楊麗芹
A17: 114年8月 | B17: 正 | C17: F224490326 | D17: N0174 | E17: 居服員 | F17: 曾馨幼 | G17: 時薪 | H17: 699513899681 | I17: 0922297795 | J17: 200 | L17: 66 | M17: 200 | N17: 50 | O17: 153 | P17: 0 | Q17: 0 | R17: 30.5 | S17: 183.5 | T17: 30600 | U17: 12200 | V17: 9175 | W17: 0 | X17: 51975 | Y17: 114/08/01 | Z17: 45800 | AA17: 1145 | AB17: 55400 | AC17: 1718 | AD17: 1 | AE17: 0 | AF17: 210 | AG17: 0 | AH17: 2863 | AI17: 49112 | AJ17: 0 | AK17: 49112 | AL17: 3324 | BT17: 林佩潔 | BV17: 0 | BX17: 林佩潔 | BZ17: 56 | CB17: 陳得聖 | CC17: 1950 | CD17: 7700 | CF17: 陳得聖
A18: 114年9月 | B18: 正 | C18: F224490326 | D18: N0174 | E18: 居服員 | F18: 曾馨幼 | G18: 時薪 | H18: 699513899681 | I18: 0922297795 | J18: 200 | L18: 66 | M18: 200 | N18: 50 | O18: 124 | P18: 0 | Q18: 0 | R18: 30 | S18: 154 | T18: 24800 | U18: 12000 | V18: 7700 | W18: 0 | X18: 44500 | Y18: 114/08/01 | Z18: 45800 | AA18: 1145 | AB18: 55400 | AC18: 1718 | AD18: 1 | AE18: 0 | AF18: -230 | AG18: 0 | AH18: 2863 | AI18: 41637 | AJ18: 0 | AK18: 41637 | AL18: 3324 | BT18: 王沛慈 | BV18: 0 | BX18: 王沛慈 | BZ18: 57 | CB18: 楊麗芹 | CC18: 67415 | CD18: 17720 | CF18: 楊麗芹
A19: 114年9月(2) | B19: 正 | C19: F224490326 | D19: N0174 | E19: 居服員 | F19: 曾馨幼 | G19: 時薪 | H19: 699513899681 | I19: 0922297795 | J19: 200 | L19: 66 | M19: 200 | N19: 50 | W19: 6610 | X19: 6610 | AI19: 6610 | AJ19: 0 | AK19: 6610
A20: 114年10月 | B20: 正 | C20: F224490326 | D20: N0174 | E20: 居服員 | F20: 曾馨幼 | G20: 時薪 | H20: 699513899681 | I20: 0922297795 | J20: 200 | L20: 66 | M20: 200 | N20: 50 | O20: 117.67 | P20: 0 | Q20: 0 | R20: 38.33 | S20: 156 | T20: 23534 | U20: 15332 | V20: 7800 | W20: 0 | X20: 46666 | Y20: 114/08/01 | Z20: 45800 | AA20: 1145 | AB20: 55400 | AC20: 1718 | AD20: 1 | AE20: 0 | AF20: -184 | AG20: 0 | AH20: 2863 | AI20: 43803 | AJ20: 0 | AK20: 43803 | AL20: 3324 | BT20: 王沛慈 | BV20: 0 | BX20: 王沛慈 | BZ20: 57 | CB20: 陳得聖 | CC20: 1560 | CD20: 6160 | CF20: 陳得聖
A21: 114年11月 | B21: 正 | C21: F224490326 | D21: N0174 | E21: 居服員 | F21: 曾馨幼 | G21: 時薪 | H21: 699513899681 | I21: 0922297795 | J21: 200 | L21: 66 | M21: 200 | N21: 50 | O21: 116.67 | P21: 0 | Q21: 0 | R21: 24 | S21: 140.67 | T21: 23334 | U21: 9600 | V21: 7034 | W21: 0 | X21: 39968 | Y21: 114/11/01 | Z21: 45800 | AA21: 1145 | AB21: 50600 | AC21: 1570 | AD21: 1 | AE21: 0 | AF21: -224 | AG21: 0 | AH21: 2715 | AI21: 37253 | AJ21: 0 | AK21: 37253 | AL21: 3036 | BT21: 王沛慈 | BV21: 0 | BX21: 王沛慈 | BZ21: 58 | CB21: 黃奕傑 | CC21: 31375 | CD21: 24485 | CF21: 黃奕傑
A22: 114年12月 | B22: 正 | C22: F224490326 | D22: N0174 | E22: 居服員 | F22: 曾馨幼 | G22: 時薪 | H22: 699513899681 | I22: 0922297795 | J22: 200 | L22: 66 | M22: 200 | N22: 50 | O22: 111.5 | P22: 0 | Q22: 0 | R22: 42 | S22: 153.5 | T22: 22300 | U22: 16800 | V22: 7675 | W22: 0 | X22: 46775 | Y22: 114/11/01 | Z22: 45800 | AA22: 1145 | AB22: 50600 | AC22: 1570 | AD22: 1 | AE22: 0 | AF22: -81 | AG22: 0 | AH22: 2715 | AI22: 44060 | AJ22: 0 | AK22: 44060 | AL22: 3036 | BT22: 吳虹儒 | BV22: 0 | BX22: 吳虹儒 | BZ22: 57 | CB22: 王麗雯 | CC22: 49930 | CD22: 20189.3 | CF22: 王麗雯
C25: 員工名稱 | D25: =F6 -> 曾馨幼 | E25: 身份證字號 | F25: =C6 -> F224490326 | H25: 地址
D26: 十二月 | E26: 一月 | F26: 二月 | G26: 三月 | H26: 四月 | I26: 五月 | J26: 六月 | K26: 七月 | L26: 八月 | M26: 九月 | N26: 十月 | O26: 十一月 | P26: 合計 | Q26: 申報金額
C27: 薪資 | D27: =$X$6 -> 57070 | E27: =$X$8 -> 47418 | F27: =$X$9 -> 53612 | G27: =$X$10 -> 53268 | H27: =$X$12 -> 56558 | I27: =$X$13 -> 51181 | J27: =$X$14 -> 58194 | K27: =$X$16 -> 52987 | L27: =$X$17 -> 51975 | M27: =$X$18 -> 44500 | N27: =$X$20 -> 46666 | O27: =$X$21 -> 39968 | P27: =SUM(D27:O27) -> 613397 | Q27: =P27+P28 -> 660550
C28: 獎金 | D28: =$X$7 -> 15420 | E28: 0 | F28: 0 | G28: =$X$11 -> 13470 | H28: 0 | I28: 0 | J28: =$X$15 -> 11653 | K28: 0 | L28: 0 | M28: =$X$19 -> 6610 | N28: 0 | O28: 0 | P28: =SUM(D28:O28) -> 47153
C29: 投保金額 | D29: =$AB$6 -> 53000 | E29: =$AB$8 -> 53000 | F29: =$AB$9 -> 53000 | G29: =$AB$10 -> 53000 | H29: =$AB$12 -> 53000 | I29: =$AB$13 -> 53000 | J29: =$AB$14 -> 53000 | K29: =$AB$16 -> 53000 | L29: =$AB$17 -> 55400 | M29: =$AB$18 -> 55400 | N29: =$AB$20 -> 55400 | O29: =$AB$21 -> 50600 | P29: =SUM(D29:O29) -> 640800

Sheet AA碼季獎金
A10: 建立時間: 2023/10/26下午 06:40:06
A11: 新北市私立五棵松居家長照機構 2023年09月 員工拆帳明細表
A13: 一般/偏鄉 | B13: 項目名稱 | C13: 編號 | D13: 單價 | E13: 組數 | F13: 小計 | G13: 組數 | H13: 組數 | I13: 組數 | J13: 組數 | K13: 組數 | L13: 組數 | M13: 組數 | N13: 組數 | O13: 組數 | P13: 組數 | Q13: 組數 | R13: 組數 | S13: 組數 | T13: 組數 | U13: 組數 | V13: 組數 | W13: 組數 | X13: 組數 | Y13: 組數 | Z13: 組數 | AA13: 組數 | AB13: 組數 | AC13: 組數 | AD13: 組數 | AE13: 組數 | AF13: 組數 | AG13: 組數 | AH13: 組數 | AI13: 組數 | AJ13: 組數 | AK13: 組數 | AL13: 組數 | AM13: 組數 | AN13: 組數 | AO13: 組數 | AP13: 組數
A18: 建立時間: 2024/1/31上午 01:46:32
A19: 新北市私立五棵松居家長照機構 2023年10月 員工拆帳明細表
A20: 曾馨幼 | E20: 拆帳金額 | F20: 2260 | G20: 李美慧 | H20: 雷秀花 | I20: 劉玉麟 | J20: 謝惇
A21: 一般/偏鄉 | B21: 項目名稱 | C21: 編號 | D21: 單價 | E21: 組數 | F21: 小計 | G21: 組數 | H21: 組數 | I21: 組數 | J21: 組數 | K21: 組數 | L21: 組數 | M21: 組數 | N21: 組數 | O21: 組數 | P21: 組數 | Q21: 組數 | R21: 組數 | S21: 組數 | T21: 組數 | U21: 組數 | V21: 組數 | W21: 組數 | X21: 組數 | Y21: 組數 | Z21: 組數 | AA21: 組數 | AB21: 組數 | AC21: 組數 | AD21: 組數 | AE21: 組數 | AF21: 組數 | AG21: 組數 | AH21: 組數 | AI21: 組數 | AJ21: 組數 | AK21: 組數 | AL21: 組數 | AM21: 組數 | AN21: 組數 | AO21: 組數 | AP21: 組數
A22: 一般價格 | B22: 照顧困難之服務加計 | C22: AA05(10712) | D22: $ 200(60) | E22: 21 | F22: 1260 | G22: 1 | J22: 20
A23: 一般價格 | B23: 例假日服務 | C23: AA09 | D23: 770 | E23: 2 | F23: 0 | H23: 1 | I23: 1
A24: 一般價格 | B24: 照顧服務員進階訓練 | C24: AA11 | D24: 50 | E24: 20 | F24: 1000 | J24: 20
A29: 建立時間: 2024/1/31上午 02:36:09
A30: 新北市私立五棵松居家長照機構 2023年11月 員工拆帳明細表
A31: 曾馨幼 | E31: 拆帳金額 | F31: 2480 | G31: 雷秀花 | H31: 劉玉麟 | I31: 錢淑儀 | J31: 謝惇
A32: 一般/偏鄉 | B32: 項目名稱 | C32: 編號 | D32: 單價 | E32: 組數 | F32: 小計 | G32: 組數 | H32: 組數 | I32: 組數 | J32: 組數 | K32: 組數 | L32: 組數 | M32: 組數 | N32: 組數 | O32: 組數 | P32: 組數 | Q32: 組數 | R32: 組數 | S32: 組數 | T32: 組數 | U32: 組數 | V32: 組數 | W32: 組數 | X32: 組數 | Y32: 組數 | Z32: 組數 | AA32: 組數 | AB32: 組數 | AC32: 組數 | AD32: 組數 | AE32: 組數 | AF32: 組數 | AG32: 組數 | AH32: 組數 | AI32: 組數 | AJ32: 組數 | AK32: 組數 | AL32: 組數 | AM32: 組數 | AN32: 組數 | AO32: 組數 | AP32: 組數
A33: 一般價格 | B33: 照顧困難之服務加計 | C33: AA05(10712) | D33: $ 200(60) | E33: 23 | F33: 1380 | I33: 1 | J33: 22
A34: 一般價格 | B34: 例假日服務 | C34: AA09 | D34: 770 | E34: 2 | F34: 0 | G34: 1 | H34: 1
A35: 一般價格 | B35: 照顧服務員進階訓練 | C35: AA11 | D35: 50 | E35: 22 | F35: 1100 | J35: 22
A40: 建立時間: 2024/1/31上午 02:51:10
A41: 新北市私立五棵松居家長照機構 2023年12月 員工拆帳明細表
A42: 曾馨幼 | E42: 拆帳金額 | F42: 2430 | G42: 李美慧 | H42: 張吳材妹 | I42: 雷秀花 | J42: 劉玉麟 | K42: 謝惇
A43: 一般/偏鄉 | B43: 項目名稱 | C43: 編號 | D43: 單價 | E43: 組數 | F43: 小計 | G43: 組數 | H43: 組數 | I43: 組數 | J43: 組數 | K43: 組數 | L43: 組數 | M43: 組數 | N43: 組數 | O43: 組數 | P43: 組數 | Q43: 組數 | R43: 組數 | S43: 組數 | T43: 組數 | U43: 組數 | V43: 組數 | W43: 組數 | X43: 組數 | Y43: 組數 | Z43: 組數 | AA43: 組數 | AB43: 組數 | AC43: 組數 | AD43: 組數 | AE43: 組數 | AF43: 組數 | AG43: 組數 | AH43: 組數 | AI43: 組數 | AJ43: 組數 | AK43: 組數 | AL43: 組數 | AM43: 組數 | AN43: 組數 | AO43: 組數 | AP43: 組數
A44: 一般價格 | B44: 照顧困難之服務加計 | C44: AA05(10712) | D44: $ 200(60) | E44: 23 | F44: 1380 | G44: 1 | H44: 1 | K44: 21
A45: 一般價格 | B45: 例假日服務 | C45: AA09 | D45: 770 | E45: 2 | F45: 0 | I45: 1 | J45: 1
A46: 一般價格 | B46: 照顧服務員進階訓練 | C46: AA11 | D46: 50 | E46: 21 | F46: 1050 | K46: 21
A48: 112年第4季AA碼獎金= | C48: =$F$20 -> 2260
A49: =SUM(C48:C50) -> 7170 | C49: 2480
C50: 2430
A54: 建立時間: 2024/4/30上午 12:47:47
A55: 新北市私立五棵松居家長照機構 2024年01月 員工拆帳明細表
A56: 曾馨幼 | E56: 拆帳金額 | F56: =SUM(F58:F60) -> 2430 | G56: 雷秀花 | H56: 劉玉麟 | I56: 錢淑儀 | J56: 謝惇
A57: 一般/偏鄉 | B57: 項目名稱 | C57: 編號 | D57: 單價 | E57: 組數 | F57: 小計 | G57: 組數 | H57: 組數 | I57: 組數 | J57: 組數 | K57: 組數 | L57: 組數 | M57: 組數 | N57: 組數 | O57: 組數 | P57: 組數 | Q57: 組數 | R57: 組數 | S57: 組數 | T57: 組數 | U57: 組數 | V57: 組數 | W57: 組數 | X57: 組數 | Y57: 組數 | Z57: 組數 | AA57: 組數 | AB57: 組數 | AC57: 組數 | AD57: 組數 | AE57: 組數 | AF57: 組數 | AG57: 組數 | AH57: 組數 | AI57: 組數 | AJ57: 組數 | AK57: 組數 | AL57: 組數 | AM57: 組數 | AN57: 組數 | AO57: 組數 | AP57: 組數
A58: 一般價格 | B58: 照顧困難之服務加計 | C58: AA05(10712) | D58: 60 | E58: =SUM(G58:AP58) -> 23 | F58: =D58*E58 -> 1380 | I58: 2 | J58: 21
A59: 一般價格 | B59: 例假日服務 | C59: AA09 | D59: 0 | E59: =SUM(G59:AP59) -> 2 | F59: =D59*E59 -> 0 | G59: 1 | H59: 1
A60: 一般價格 | B60: 照顧服務員進階訓練 | C60: AA11 | D60: 50 | E60: =SUM(G60:AP60) -> 21 | F60: =D60*E60 -> 1050 | J60: 21
A65: 建立時間: 2024/4/30上午 02:02:46
A66: 新北市私立五棵松居家長照機構 2024年02月 員工拆帳明細表
A67: 曾馨幼 | E67: 拆帳金額 | F67: =SUM(F69:F72) -> 2260 | G67: 李元勳 | H67: 張吳材妹 | I67: 張偉良 | J67: 張陳碧霞 | K67: 陳巧雲 | L67: 黃碧娟 | M67: 劉玉麟 | N67: 謝惇
A68: 一般/偏鄉 | B68: 項目名稱 | C68: 編號 | D68: 單價 | E68: 組數 | F68: 小計 | G68: 組數 | H68: 組數 | I68: 組數 | J68: 組數 | K68: 組數 | L68: 組數 | M68: 組數 | N68: 組數 | O68: 組數 | P68: 組數 | Q68: 組數 | R68: 組數 | S68: 組數 | T68: 組數 | U68: 組數 | V68: 組數 | W68: 組數 | X68: 組數 | Y68: 組數 | Z68: 組數 | AA68: 組數 | AB68: 組數 | AC68: 組數 | AD68: 組數 | AE68: 組數 | AF68: 組數 | AG68: 組數 | AH68: 組數 | AI68: 組數 | AJ68: 組數 | AK68: 組數 | AL68: 組數 | AM68: 組數 | AN68: 組數 | AO68: 組數 | AP68: 組數
A69: 一般價格 | B69: 照顧困難之服務加計 | C69: AA05(10712) | D69: 60 | E69: =SUM(G69:AP69) -> 21 | F69: =D69*E69 -> 1260 | H69: 3 | L69: 2 | N69: 16
A70: 一般價格 | B70: 家庭照顧功能微弱之服務加計 | C70: AA07(10712) | D70: 200 | E70: =SUM(G70:AP70) -> 1 | F70: =D70*E70 -> 200 | L70: 1
...

Sheet format
A6: 項目(A1) | B6: 薪資/小時 (a) | C6: 200
B7: 工作加給/小時 (aa)
B8: 平日服務時數 (b)
B9: 本薪 (c)
B10: 平日加班加給/小時 (d) | C10: 66
B11: 平日加班時數 (e)
B12: 平日延長加班/假日(休息及國定) 加給/小時 (f) | C12: 200
B13: 延長加班+例假日服務時數 (g)
B14: 總加班費 (h)
B15: 津貼/小時 (i) | C15: 50
B16: 總津貼(50*總工作時數 ) (j)
A17: 獎金(A2)
A18: 應發薪資(A) | B18: A1(c+h+j)+A2
A19: 個人扣項
B21: 二代健保 (m)
B22: 自提勞退 (n)
A23: 應扣總款(B) | B23: k+l+m+n
A24: 支領現金
A25: 實發薪資(C) | B25: 銀行薪轉金額
A26: 勞退 (D) | B26: 機構負擔勞退6%
A27: 實得薪資 | C27: =C25+C26 -> 0
A28: 備註
